Workbook
Name Slicer_Diabetes_Status: #N/A
Name Slicer_DIABETES_STATUS1: #N/A
Name Slicer_Weight_Status: #N/A
Name Slicer_WEIGHT_STATUS1: #N/A

Sheet Customer Names
A1: Customer ID | B1: name | C1: FIRST NAME
A2: Id1 | B2: Hawks, Ms. Kelly | C2: Kelly | D2: using flash fill
A3: Id2 | B3: Lehner, Mr. Matthew D | C3: Matthew D
A4: Id3 | B4: Lu, Mr. Phil | C4: Phil
A5: Id4 | B5: Osborne, Ms. Kelsey | C5: Kelsey
A6: Id5 | B6: Kadala, Ms. Kristyn | C6: Kristyn
A7: Id6 | B7: Baker, Mr. Russell B. | C7: Russell B.
A8: Id7 | B8: Macpherson, Mr. Scott | C8: Scott
A9: Id8 | B9: Hallman, Mr. Stephen | C9: Stephen
A10: Id9 | B10: Moran, Mr. Patrick R. | C10: Patrick R.
A11: Id10 | B11: Benner, Ms. Brooke N. | C11: Brooke N.
A12: Id11 | B12: Fierro Vargas, Ms. Paola Andrea | C12: Ms. Paola Andrea
A13: Id12 | B13: Franz, Mr. David | C13: David
A14: Id13 | B14: Foster, Mr. Wade | C14: Wade
... A2336: Id2335 | B2336: German, Mr. Aaron K | C2336: Aaron K

Sheet Medical Examinations
A1: Customer ID | B1: BMI | C1: HBA1C | D1: Heart Issues | E1: Any Transplants | F1: Cancer history | G1: NumberOfMajorSurgeries | H1: smoker | I1: Weight Status | J1: Diabetes Status
A2: Id1 | B2: 47.41 | C2: 7.47 | D2: No | E2: No | F2: No | G2: 0 | H2: yes | I2: =IF(B2<18.5,"UNDERWEIGHT",IF(AND(B2>=18.5,B2<=24.9),"NORMAL WEIGHT",IF(AND(B2>25,B2<=29.9),"OVERWEIGHT",IF(B2>=30,"OBESITY")))) -> OBESITY | J2: =IF(C2<5.7,"NORMAL",IF(AND(C2>=5.7,C2<=6.4),"PREDIABETES",IF(C2>6.4,"DIABETES"))) -> DIABETES
A3: Id2 | B3: 30.36 | C3: 5.77 | D3: No | E3: No | F3: No | G3: 0 | H3: yes | I3: =IF(B3<18.5,"UNDERWEIGHT",IF(AND(B3>=18.5,B3<=24.9),"NORMAL WEIGHT",IF(AND(B3>25,B3<=29.9),"OVERWEIGHT",IF(B3>=30,"OBESITY")))) -> OBESITY | J3: =IF(C3<5.7,"NORMAL",IF(AND(C3>=5.7,C3<=6.4),"PREDIABETES",IF(C3>6.4,"DIABETES"))) -> PREDIABETES
A4: Id3 | B4: 34.485 | C4: 11.87 | D4: yes | E4: No | F4: No | G4: 2 | H4: yes | I4: =IF(B4<18.5,"UNDERWEIGHT",IF(AND(B4>=18.5,B4<=24.9),"NORMAL WEIGHT",IF(AND(B4>25,B4<=29.9),"OVERWEIGHT",IF(B4>=30,"OBESITY")))) -> OBESITY | J4: =IF(C4<5.7,"NORMAL",IF(AND(C4>=5.7,C4<=6.4),"PREDIABETES",IF(C4>6.4,"DIABETES"))) -> DIABETES
A5: Id4 | B5: 38.095 | C5: 6.05 | D5: No | E5: No | F5: No | G5: 0 | H5: yes | I5: =IF(B5<18.5,"UNDERWEIGHT",IF(AND(B5>=18.5,B5<=24.9),"NORMAL WEIGHT",IF(AND(B5>25,B5<=29.9),"OVERWEIGHT",IF(B5>=30,"OBESITY")))) -> OBESITY | J5: =IF(C5<5.7,"NORMAL",IF(AND(C5>=5.7,C5<=6.4),"PREDIABETES",IF(C5>6.4,"DIABETES"))) -> PREDIABETES
A6: Id5 | B6: 35.53 | C6: 5.45 | D6: No | E6: No | F6: No | G6: 0 | H6: yes | I6: =IF(B6<18.5,"UNDERWEIGHT",IF(AND(B6>=18.5,B6<=24.9),"NORMAL WEIGHT",IF(AND(B6>25,B6<=29.9),"OVERWEIGHT",IF(B6>=30,"OBESITY")))) -> OBESITY | J6: =IF(C6<5.7,"NORMAL",IF(AND(C6>=5.7,C6<=6.4),"PREDIABETES",IF(C6>6.4,"DIABETES"))) -> NORMAL
A7: Id6 | B7: 32.8 | C7: 6.59 | D7: No | E7: No | F7: No | G7: 0 | H7: yes | I7: =IF(B7<18.5,"UNDERWEIGHT",IF(AND(B7>=18.5,B7<=24.9),"NORMAL WEIGHT",IF(AND(B7>25,B7<=29.9),"OVERWEIGHT",IF(B7>=30,"OBESITY")))) -> OBESITY | J7: =IF(C7<5.7,"NORMAL",IF(AND(C7>=5.7,C7<=6.4),"PREDIABETES",IF(C7>6.4,"DIABETES"))) -> DIABETES
A8: Id7 | B8: 36.4 | C8: 6.07 | D8: No | E8: No | F8: No | G8: 0 | H8: yes | I8: =IF(B8<18.5,"UNDERWEIGHT",IF(AND(B8>=18.5,B8<=24.9),"NORMAL WEIGHT",IF(AND(B8>25,B8<=29.9),"OVERWEIGHT",IF(B8>=30,"OBESITY")))) -> OBESITY | J8: =IF(C8<5.7,"NORMAL",IF(AND(C8>=5.7,C8<=6.4),"PREDIABETES",IF(C8>6.4,"DIABETES"))) -> PREDIABETES
A9: Id8 | B9: 36.96 | C9: 7.93 | D9: No | E9: No | F9: No | G9: 3 | H9: yes | I9: =IF(B9<18.5,"UNDERWEIGHT",IF(AND(B9>=18.5,B9<=24.9),"NORMAL WEIGHT",IF(AND(B9>25,B9<=29.9),"OVERWEIGHT",IF(B9>=30,"OBESITY")))) -> OBESITY | J9: =IF(C9<5.7,"NORMAL",IF(AND(C9>=5.7,C9<=6.4),"PREDIABETES",IF(C9>6.4,"DIABETES"))) -> DIABETES
A10: Id9 | B10: 41.14 | C10: 9.58 | D10: yes | E10: No | F10: Yes | G10: 1 | H10: yes | I10: =IF(B10<18.5,"UNDERWEIGHT",IF(AND(B10>=18.5,B10<=24.9),"NORMAL WEIGHT",IF(AND(B10>25,B10<=29.9),"OVERWEIGHT",IF(B10>=30,"OBESITY")))) -> OBESITY | J10: =IF(C10<5.7,"NORMAL",IF(AND(C10>=5.7,C10<=6.4),"PREDIABETES",IF(C10>6.4,"DIABETES"))) -> DIABETES
A11: Id10 | B11: 38.06 | C11: 10.79 | D11: No | E11: No | F11: No | G11: 0 | H11: yes | I11: =IF(B11<18.5,"UNDERWEIGHT",IF(AND(B11>=18.5,B11<=24.9),"NORMAL WEIGHT",IF(AND(B11>25,B11<=29.9),"OVERWEIGHT",IF(B11>=30,"OBESITY")))) -> OBESITY | J11: =IF(C11<5.7,"NORMAL",IF(AND(C11>=5.7,C11<=6.4),"PREDIABETES",IF(C11>6.4,"DIABETES"))) -> DIABETES
A12: Id11 | B12: 37.7 | C12: 5.96 | D12: yes | E12: No | F12: No | G12: 2 | H12: yes | I12: =IF(B12<18.5,"UNDERWEIGHT",IF(AND(B12>=18.5,B12<=24.9),"NORMAL WEIGHT",IF(AND(B12>25,B12<=29.9),"OVERWEIGHT",IF(B12>=30,"OBESITY")))) -> OBESITY | J12: =IF(C12<5.7,"NORMAL",IF(AND(C12>=5.7,C12<=6.4),"PREDIABETES",IF(C12>6.4,"DIABETES"))) -> PREDIABETES
A13: Id12 | B13: 42.13 | C13: 11.9 | D13: No | E13: No | F13: No | G13: 0 | H13: yes | I13: =IF(B13<18.5,"UNDERWEIGHT",IF(AND(B13>=18.5,B13<=24.9),"NORMAL WEIGHT",IF(AND(B13>25,B13<=29.9),"OVERWEIGHT",IF(B13>=30,"OBESITY")))) -> OBESITY | J13: =IF(C13<5.7,"NORMAL",IF(AND(C13>=5.7,C13<=6.4),"PREDIABETES",IF(C13>6.4,"DIABETES"))) -> DIABETES
... A2336: Id2335 | B2336: 17.58 | C2336: 4.51 | D2336: No | E2336: No | F2336: No | G2336: 1 | H2336: No | I2336: =IF(B2336<18.5,"UNDERWEIGHT",IF(AND(B2336>=18.5,B2336<=24.9),"NORMAL WEIGHT",IF(AND(B2336>25,B2336<=29.9),"OVERWEIGHT",IF(B2336>=30,"OBESITY")))) -> UNDERWEIGHT | J2336: =IF(C2336<5.7,"NORMAL",IF(AND(C2336>=5.7,C2336<=6.4),"PREDIABETES",IF(C2336>6.4,"DIABETES"))) -> NORMAL

Sheet Hospitalisation Details
A1: Customer ID | B1: year | C1: month | D1: date | E1: children | F1: charges | G1: Hospital tier | H1: City tier | I1: State ID | J1: dob | K1: age
A2: Id2335 | B2: 1992 | C2: Jul | D2: 9 | E2: 0 | F2: 563.84 | G2: tier - 2 | H2: tier - 3 | I2: R1013 | J2: =CONCATENATE(D2,"-",C2,"-",B2) -> 9-Jul-1992 | K2: =DATEDIF(J2,TODAY(),"y") -> 33
A3: Id2334 | B3: 1992 | C3: Nov | D3: 30 | E3: 0 | F3: 570.62 | G3: tier - 2 | H3: tier - 1 | I3: R1013 | J3: =CONCATENATE(D3,"-",C3,"-",B3) -> 30-Nov-1992 | K3: =DATEDIF(J3,TODAY(),"y") -> 32
A4: Id2333 | B4: 1993 | C4: Jun | D4: 30 | E4: 0 | F4: 600 | G4: tier - 2 | H4: tier - 1 | I4: R1013 | J4: =CONCATENATE(D4,"-",C4,"-",B4) -> 30-Jun-1993 | K4: =DATEDIF(J4,TODAY(),"y") -> 32
A5: Id2332 | B5: 1992 | C5: Sep | D5: 13 | E5: 0 | F5: 604.54 | G5: tier - 3 | H5: tier - 3 | I5: R1013 | J5: =CONCATENATE(D5,"-",C5,"-",B5) -> 13-Sep-1992 | K5: =DATEDIF(J5,TODAY(),"y") -> 33
A6: Id2331 | B6: 1998 | C6: Jul | D6: 27 | E6: 0 | F6: 637.26 | G6: tier - 3 | H6: tier - 3 | I6: R1013 | J6: =CONCATENATE(D6,"-",C6,"-",B6) -> 27-Jul-1998 | K6: =DATEDIF(J6,TODAY(),"y") -> 27
A7: Id2330 | B7: 2001 | C7: Nov | D7: 20 | E7: 0 | F7: 646.14 | G7: tier - 3 | H7: tier - 3 | I7: R1012 | J7: =CONCATENATE(D7,"-",C7,"-",B7) -> 20-Nov-2001 | K7: =DATEDIF(J7,TODAY(),"y") -> 23
A8: Id2329 | B8: 1993 | C8: Jun | D8: 1 | E8: 0 | F8: 650 | G8: tier - 3 | H8: tier - 3 | I8: R1013 | J8: =CONCATENATE(D8,"-",C8,"-",B8) -> 1-Jun-1993 | K8: =DATEDIF(J8,TODAY(),"y") -> 32
A9: Id2328 | B9: 1995 | C9: Jul | D9: 4 | E9: 0 | F9: 650 | G9: tier - 3 | H9: tier - 3 | I9: R1013 | J9: =CONCATENATE(D9,"-",C9,"-",B9) -> 4-Jul-1995 | K9: =DATEDIF(J9,TODAY(),"y") -> 30
A10: Id2327 | B10: 2002 | C10: Nov | D10: 29 | E10: 0 | F10: 668 | G10: tier - 3 | H10: tier - 2 | I10: R1012 | J10: =CONCATENATE(D10,"-",C10,"-",B10) -> 29-Nov-2002 | K10: =DATEDIF(J10,TODAY(),"y") -> 22
A11: Id2326 | B11: 1997 | C11: Nov | D11: 9 | E11: 0 | F11: 670 | G11: tier - 3 | H11: tier - 3 | I11: R1013 | J11: =CONCATENATE(D11,"-",C11,"-",B11) -> 9-Nov-1997 | K11: =DATEDIF(J11,TODAY(),"y") -> 28
A12: Id2325 | B12: 2001 | C12: Sep | D12: 12 | E12: 0 | F12: 687.54 | G12: tier - 3 | H12: tier - 2 | I12: R1013 | J12: =CONCATENATE(D12,"-",C12,"-",B12) -> 12-Sep-2001 | K12: =DATEDIF(J12,TODAY(),"y") -> 24
A13: Id2324 | B13: 1999 | C13: Dec | D13: 26 | E13: 0 | F13: 700 | G13: tier - 2 | H13: tier - 3 | I13: R1013 | J13: =CONCATENATE(D13,"-",C13,"-",B13) -> 26-Dec-1999 | K13: =DATEDIF(J13,TODAY(),"y") -> 25
... A2344: Id1 | B2344: 1968 | C2344: Oct | D2344: 12 | E2344: 0 | F2344: 63770.43 | G2344: tier - 1 | H2344: tier - 3 | I2344: R1013 | J2344: =CONCATENATE(D2344,"-",C2344,"-",B2344) -> 12-Oct-1968 | K2344: =DATEDIF(J2344,TODAY(),"y") -> 57

Sheet Data Cleaning
A1: 1 | F1: 2 | G1: year | H1: month | I1: 3 | J1: smoker | K1: Hospital tier | L1: City tier | Q1: 4 | R1: State ID | Y1: Customer ID | Z1: BMI | AA1: HBA1C | AB1: Heart Issues | AC1: Any Transplants | AD1: Cancer history | AE1: NumberOfMajorSurgeries | AF1: smoker | AH1: Customer ID | AI1: year | AJ1: month | AK1: date | AL1: children | AM1: charges | AN1: Hospital tier | AO1: City tier | AP1: State ID
B2: No: of Missing Values(?) | E2: ? | G2: 1992 | H2: Jul | J2: yes | K2: tier - 2 | L2: tier - 3 | M2: Smoker | R2: R1013 | Y2: Id1 | Z2: 47.41 | AA2: 7.47 | AB2: No | AC2: No | AD2: No | AE2: No major surgery | AF2: yes | AH2: Id2335 | AI2: 1992 | AJ2: Jul | AK2: 9 | AL2: 0 | AM2: 563.84 | AN2: tier - 2 | AO2: tier - 3 | AP2: R1013
B3: Medical Examination Table | D3: =COUNTIF(Y2:AF2336,E2) -> 2 | G3: 1992 | H3: Nov | J3: yes | K3: tier - 2 | L3: tier - 1 | M3: yes | N3: =COUNTIF(J2:J2336,M3) -> 488 | R3: R1013 | Y3: Id2 | Z3: 30.36 | AA3: 5.77 | AB3: No | AC3: No | AD3: No | AE3: No major surgery | AF3: yes | AH3: Id2334 | AI3: 1992 | AJ3: Nov | AK3: 30 | AL3: 0 | AM3: 570.62 | AN3: tier - 2 | AO3: tier - 1 | AP3: R1013
B4: Hosptalisation Details | D4: =COUNTIF(AH2:AP2344,E2) -> 15 | F4: AVERAGE | G4: 1993 | H4: Jun | J4: yes | K4: tier - 2 | L4: tier - 1 | M4: No | N4: =COUNTIF(J3:J2337,M4) -> 1847 | O4: (most frequent) | R4: R1013 | Y4: Id3 | Z4: 34.485 | AA4: 11.87 | AB4: yes | AC4: No | AD4: No | AE4: 2 | AF4: yes | AH4: Id2333 | AI4: 1993 | AJ4: Jun | AK4: 30 | AL4: 0 | AM4: 600 | AN4: tier - 2 | AO4: tier - 1 | AP4: R1013
F5: =AVERAGE(G2:G2344) -> 1982.8417 | G5: 1992 | H5: Sep | J5: yes | K5: tier - 3 | L5: tier - 3 | R5: R1013 | Y5: Id4 | Z5: 38.095 | AA5: 6.05 | AB5: No | AC5: No | AD5: No | AE5: No major surgery | AF5: yes | AH5: Id2332 | AI5: 1992 | AJ5: Sep | AK5: 13 | AL5: 0 | AM5: 604.54 | AN5: tier - 3 | AO5: tier - 3 | AP5: R1013
F6: =ROUND(F5,0) -> 1983 | G6: 1998 | H6: Jul | J6: yes | K6: tier - 3 | L6: tier - 3 | M6: Hospital tier | R6: R1013 | Y6: Id5 | Z6: 35.53 | AA6: 5.45 | AB6: No | AC6: No | AD6: No | AE6: No major surgery | AF6: yes | AH6: Id2331 | AI6: 1998 | AJ6: Jul | AK6: 27 | AL6: 0 | AM6: 637.26 | AN6: tier - 3 | AO6: tier - 3 | AP6: R1013
G7: 2001 | H7: Nov | J7: yes | K7: tier - 3 | L7: tier - 3 | M7: tier - 1 | N7: =COUNTIF('Data Cleaning'!K2:K2344,M7) -> 309 | R7: R1012 | Y7: Id6 | Z7: 32.8 | AA7: 6.59 | AB7: No | AC7: No | AD7: No | AE7: No major surgery | AF7: yes | AH7: Id2330 | AI7: 2001 | AJ7: Nov | AK7: 20 | AL7: 0 | AM7: 646.14 | AN7: tier - 3 | AO7: tier - 3 | AP7: R1012
G8: 1993 | H8: Jun | J8: yes | K8: tier - 3 | L8: tier - 3 | M8: tier - 2 | N8: =COUNTIF('Data Cleaning'!K3:K2345,M8) -> 1339 | O8: (most frequent) | R8: R1013 | Y8: Id7 | Z8: 36.4 | AA8: 6.07 | AB8: No | AC8: No | AD8: No | AE8: No major surgery | AF8: yes | AH8: Id2329 | AI8: 1993 | AJ8: Jun | AK8: 1 | AL8: 0 | AM8: 650 | AN8: tier - 3 | AO8: tier - 3 | AP8: R1013
G9: 1995 | H9: Jul | J9: yes | K9: tier - 3 | L9: tier - 3 | M9: tier - 3 | N9: =COUNTIF('Data Cleaning'!K4:K2346,M9) -> 694 | R9: R1013 | Y9: Id8 | Z9: 36.96 | AA9: 7.93 | AB9: No | AC9: No | AD9: No | AE9: 3 | AF9: yes | AH9: Id2328 | AI9: 1995 | AJ9: Jul | AK9: 4 | AL9: 0 | AM9: 650 | AN9: tier - 3 | AO9: tier - 3 | AP9: R1013
G10: 2002 | H10: Nov | J10: yes | K10: tier - 3 | L10: tier - 2 | R10: R1012 | Y10: Id9 | Z10: 41.14 | AA10: 9.58 | AB10: yes | AC10: No | AD10: Yes | AE10: 1 | AF10: yes | AH10: Id2327 | AI10: 2002 | AJ10: Nov | AK10: 29 | AL10: 0 | AM10: 668 | AN10: tier - 3 | AO10: tier - 2 | AP10: R1012
G11: 1997 | H11: Nov | J11: yes | K11: tier - 3 | L11: tier - 3 | M11: City tier | R11: R1013 | Y11: Id10 | Z11: 38.06 | AA11: 10.79 | AB11: No | AC11: No | AD11: No | AE11: No major surgery | AF11: yes | AH11: Id2326 | AI11: 1997 | AJ11: Nov | AK11: 9 | AL11: 0 | AM11: 670 | AN11: tier - 3 | AO11: tier - 3 | AP11: R1013
G12: 2001 | H12: Sep | J12: yes | K12: tier - 3 | L12: tier - 2 | M12: tier - 1 | N12: =COUNTIF('Data Cleaning'!L2:L2344,M12) -> 734 | R12: R1013 | Y12: Id11 | Z12: 37.7 | AA12: 5.96 | AB12: yes | AC12: No | AD12: No | AE12: 2 | AF12: yes | AH12: Id2325 | AI12: 2001 | AJ12: Sep | AK12: 12 | AL12: 0 | AM12: 687.54 | AN12: tier - 3 | AO12: tier - 2 | AP12: R1013
G13: 1999 | H13: Dec | J13: yes | K13: tier - 2 | L13: tier - 3 | M13: tier - 2 | N13: =COUNTIF('Data Cleaning'!L3:L2345,M13) -> 813 | O13: (most frequent) | R13: R1013 | Y13: Id12 | Z13: 42.13 | AA13: 11.9 | AB13: No | AC13: No | AD13: No | AE13: No major surgery | AF13: yes | AH13: Id2324 | AI13: 1999 | AJ13: Dec | AK13: 26 | AL13: 0 | AM13: 700 | AN13: ? | AO13: tier - 3 | AP13: R1013
G14: 1999 | H14: Dec | J14: yes | K14: tier - 3 | L14: tier - 1 | M14: tier - 3 | N14: =COUNTIF('Data Cleaning'!L4:L2346,M14) -> 795 | R14: R1013 | Y14: Id13 | Z14: 40.92 | AA14: 8.41 | AB14: No | AC14: No | AD14: No | AE14: No major surgery | AF14: yes | AH14: Id2323 | AI14: 1999 | AJ14: Dec | AK14: 14 | AL14: 0 | AM14: 722.99 | AN14: tier - 3 | AO14: tier - 1 | AP14: R1013
G15: 2002 | H15: Sep | J15: yes | K15: tier - 3 | L15: tier - 1 | R15: R1012 | Y15: Id14 | Z15: 40.565 | AA15: 7.02 | AB15: No | AC15: No | AD15: No | AE15: No major surgery | AF15: yes | AH15: Id2322 | AI15: 2002 | AJ15: ? | AK15: 19 | AL15: 0 | AM15: 750 | AN15: tier - 3 | AO15: tier - 1 | AP15: R1012
G16: 1993 | H16: Aug | J16: yes | K16: tier - 3 | L16: tier - 1 | R16: R1013 | Y16: Id15 | Z16: 36.385 | AA16: 7.59 | AB16: yes | AC16: No | AD16: No | AE16: 2 | AF16: yes | AH16: Id2321 | AI16: 1993 | AJ16: Aug | AK16: 9 | AL16: 0 | AM16: 760 | AN16: tier - 3 | AO16: tier - 1 | AP16: R1013
G17: 1996 | H17: Oct | J17: yes | K17: tier - 3 | L17: tier - 3 | R17: R1013 | Y17: Id16 | Z17: 39.9 | AA17: 11.32 | AB17: No | AC17: No | AD17: No | AE17: No major surgery | AF17: yes | AH17: Id2320 | AI17: 1996 | AJ17: Oct | AK17: 22 | AL17: 0 | AM17: 760 | AN17: tier - 3 | AO17: tier - 3 | AP17: R1013
G18: 1993 | H18: Jun | J18: yes | K18: tier - 3 | L18: tier - 3 | R18: R1013 | Y18: Id17 | Z18: 33.8 | AA18: 7.67 | AB18: No | AC18: No | AD18: No | AE18: 3 | AF18: yes | AH18: Id2319 | AI18: 1993 | AJ18: Jun | AK18: 28 | AL18: 0 | AM18: 770 | AN18: tier - 3 | AO18: tier - 3 | AP18: R1013
G19: 1996 | H19: Sep | J19: yes | K19: tier - 3 | L19: tier - 2 | R19: R1012 | Y19: Id18 | Z19: 36.765 | AA19: 7.29 | AB19: yes | AC19: No | AD19: Yes | AE19: 1 | AF19: yes | AH19: Id2318 | AI19: 1996 | AJ19: ? | AK19: 18 | AL19: 0 | AM19: 770.38 | AN19: tier - 3 | AO19: ? | AP19: R1012
G20: 1995 | H20: Dec | J20: yes | K20: tier - 3 | L20: tier - 2 | R20: R1013 | Y20: Id19 | Z20: 36.955 | AA20: 4.72 | AB20: yes | AC20: No | AD20: No | AE20: 1 | AF20: yes | AH20: Id2317 | AI20: 1995 | AJ20: Dec | AK20: 7 | AL20: 0 | AM20: 773.54 | AN20: tier - 3 | AO20: tier - 2 | AP20: R1013
G21: 2004 | H21: Oct | J21: yes | K21: tier - 3 | L21: tier - 2 | R21: R1011 | Y21: Id20 | Z21: 42.9 | AA21: 11.41 | AB21: No | AC21: No | AD21: No | AE21: No major surgery | AF21: yes | AH21: Id2316 | AI21: 2004 | AJ21: Oct | AK21: 7 | AL21: 0 | AM21: 830.52 | AN21: tier - 3 | AO21: tier - 2 | AP21: R1011
G22: 2000 | H22: Nov | J22: yes | K22: tier - 3 | L22: tier - 1 | R22: R1013 | Y22: Id21 | Z22: 36.3 | AA22: 11.5 | AB22: yes | AC22: No | AD22: No | AE22: 2 | AF22: yes | AH22: Id2315 | AI22: 2000 | AJ22: Nov | AK22: 18 | AL22: 0 | AM22: 865.41 | AN22: tier - 3 | AO22: tier - 1 | AP22: R1013
G23: 1993 | H23: Nov | J23: yes | K23: tier - 3 | L23: tier - 1 | R23: R1013 | Y23: Id22 | Z23: 32.2 | AA23: 6.22 | AB23: yes | AC23: No | AD23: No | AE23: 2 | AF23: yes | AH23: Id2314 | AI23: 1993 | AJ23: Nov | AK23: 27 | AL23: 0 | AM23: 896.21 | AN23: tier - 3 | AO23: tier - 1 | AP23: R1013
G24: 1994 | H24: Oct | J24: yes | K24: tier - 3 | L24: tier - 1 | R24: R1013 | Y24: Id23 | Z24: 31.3 | AA24: 11.38 | AB24: No | AC24: No | AD24: No | AE24: 3 | AF24: yes | AH24: Id2313 | AI24: 1994 | AJ24: Oct | AK24: 30 | AL24: 0 | AM24: 915.07 | AN24: tier - 3 | AO24: tier - 1 | AP24: R1013
G25: 1995 | H25: Oct | J25: yes | K25: tier - 3 | L25: tier - 1 | R25: R1013 | Y25: Id24 | Z25: 41.8 | AA25: 7.89 | AB25: yes | AC25: No | AD25: No | AE25: 2 | AF25: yes | AH25: Id2312 | AI25: 1995 | AJ25: Oct | AK25: 28 | AL25: 0 | AM25: 928.59 | AN25: tier - 3 | AO25: tier - 1 | AP25: R1013
G26: 2001 | H26: Aug | J26: yes | K26: tier - 3 | L26: tier - 2 | R26: R1013 | Y26: Id25 | Z26: 35.09 | AA26: 4.38 | AB26: yes | AC26: No | AD26: No | AE26: 2 | AF26: yes | AH26: Id2311 | AI26: 2001 | AJ26: Aug | AK26: 19 | AL26: 0 | AM26: 964.71 | AN26: tier - 3 | AO26: tier - 2 | AP26: R1013
G27: 1994 | H27: Nov | J27: yes | K27: tier - 3 | L27: tier - 2 | R27: R1013 | Y27: Id26 | Z27: 33.88 | AA27: 7.01 | AB27: No | AC27: No | AD27: No | AE27: 3 | AF27: yes | AH27: Id2310 | AI27: 1994 | AJ27: Nov | AK27: 22 | AL27: 0 | AM27: 1006.65 | AN27: tier - 3 | AO27: tier - 2 | AP27: R1013
G28: 2000 | H28: Oct | J28: yes | K28: tier - 3 | L28: tier - 2 | R28: R1013 | Y28: Id27 | Z28: 30.875 | AA28: 11.88 | AB28: No | AC28: No | AD28: No | AE28: No major surgery | AF28: yes | AH28: Id2309 | AI28: 2000 | AJ28: Oct | AK28: 9 | AL28: 0 | AM28: 1012 | AN28: tier - 3 | AO28: tier - 2 | AP28: R1013
G29: 1999 | H29: Aug | J29: yes | K29: tier - 3 | L29: tier - 2 | R29: R1013 | Y29: Id28 | Z29: 36.86 | AA29: 5.19 | AB29: yes | AC29: No | AD29: Yes | AE29: 1 | AF29: yes | AH29: Id2308 | AI29: 1999 | AJ29: Aug | AK29: 5 | AL29: 0 | AM29: 1019 | AN29: tier - 3 | AO29: tier - 2 | AP29: R1013
G30: 1995 | H30: Oct | J30: yes | K30: tier - 3 | L30: tier - 1 | R30: R1013 | Y30: Id29 | Z30: 35.86 | AA30: 6.74 | AB30: yes | AC30: No | AD30: No | AE30: 2 | AF30: yes | AH30: Id2307 | AI30: 1995 | AJ30: Oct | AK30: 5 | AL30: 0 | AM30: 1033.74 | AN30: tier - 3 | AO30: tier - 1 | AP30: R1013
G31: 1994 | H31: Nov | J31: yes | K31: tier - 3 | L31: tier - 2 | R31: R1013 | Y31: Id30 | Z31: 37.05 | AA31: 8.44 | AB31: No | AC31: No | AD31: No | AE31: No major surgery | AF31: yes | AH31: Id2306 | AI31: 1994 | AJ31: Nov | AK31: 17 | AL31: 0 | AM31: 1044 | AN31: tier - 3 | AO31: tier - 2 | AP31: R1013
G32: 2002 | H32: Jul | J32: yes | K32: tier - 3 | L32: tier - 1 | R32: R1013 | Y32: Id31 | Z32: 43.89 | AA32: 8.71 | AB32: No | AC32: No | AD32: No | AE32: No major surgery | AF32: yes | AH32: Id2305 | AI32: 2002 | AJ32: Jul | AK32: 20 | AL32: 0 | AM32: 1047 | AN32: tier - 3 | AO32: tier - 1 | AP32: R1013
G33: 2002 | H33: Jul | J33: yes | K33: tier - 3 | L33: tier - 2 | R33: R1012 | Y33: Id32 | Z33: 42.35 | AA33: 5.08 | AB33: yes | AC33: No | AD33: No | AE33: No major surgery | AF33: yes | AH33: Id2304 | AI33: 2002 | AJ33: Jul | AK33: 1 | AL33: 0 | AM33: 1049 | AN33: tier - 3 | AO33: tier - 2 | AP33: R1012
G34: 1995 | H34: Jun | J34: yes | K34: tier - 3 | L34: tier - 2 | R34: R1013 | Y34: Id33 | Z34: 31.35 | AA34: 6.86 | AB34: No | AC34: No | AD34: No | AE34: No major surgery | AF34: yes | AH34: Id2303 | AI34: 1995 | AJ34: Jun | AK34: 1 | AL34: 0 | AM34: 1056 | AN34: tier - 3 | AO34: tier - 2 | AP34: R1013
G35: 1993 | H35: Sep | J35: yes | K35: tier - 3 | L35: tier - 1 | R35: R1013 | Y35: Id34 | Z35: 47.6 | AA35: 5.95 | AB35: yes | AC35: No | AD35: No | AE35: No major surgery | AF35: yes | AH35: Id2302 | AI35: 1993 | AJ35: Sep | AK35: 28 | AL35: 0 | AM35: 1068 | AN35: tier - 3 | AO35: tier - 1 | AP35: R1013
G36: 2004 | H36: Aug | J36: yes | K36: tier - 3 | L36: tier - 3 | R36: R1013 | Y36: Id35 | Z36: 46.2 | AA36: 6.09 | AB36: No | AC36: No | AD36: Yes | AE36: 1 | AF36: yes | AH36: Id2301 | AI36: 2004 | AJ36: Aug | AK36: 24 | AL36: 0 | AM36: 1070 | AN36: tier - 3 | AO36: tier - 3 | AP36: R1013
G37: 1997 | H37: Aug | J37: yes | K37: tier - 3 | L37: tier - 3 | R37: R1013 | Y37: Id36 | Z37: 32.015 | AA37: 11.75 | AB37: No | AC37: No | AD37: No | AE37: No major surgery | AF37: yes | AH37: Id2300 | AI37: 1997 | AJ37: Aug | AK37: 13 | AL37: 0 | AM37: 1071 | AN37: tier - 3 | AO37: tier - 3 | AP37: R1013
G38: 1998 | H38: Dec | J38: yes | K38: tier - 3 | L38: tier - 2 | R38: R1013 | Y38: Id37 | Z38: 40.565 | AA38: 7.37 | AB38: No | AC38: No | AD38: No | AE38: No major surgery | AF38: yes | AH38: Id2299 | AI38: 1998 | AJ38: Dec | AK38: 26 | AL38: 0 | AM38: 1082 | AN38: tier - 3 | AO38: tier - 2 | AP38: R1013
G39: 2002 | H39: Aug | J39: yes | K39: tier - 3 | L39: tier - 3 | R39: R1013 | Y39: Id38 | Z39: 32.45 | AA39: 11.91 | AB39: No | AC39: No | AD39: No | AE39: No major surgery | AF39: yes | AH39: Id2298 | AI39: 2002 | AJ39: Aug | AK39: 13 | AL39: 0 | AM39: 1086 | AN39: tier - 3 | AO39: tier - 3 | AP39: R1013
G40: 2004 | H40: Nov | J40: yes | K40: tier - 3 | L40: tier - 1 | R40: R1013 | Y40: Id39 | Z40: 34.96 | AA40: 6.52 | AB40: No | AC40: No | AD40: No | AE40: No major surgery | AF40: yes | AH40: Id2297 | AI40: 2004 | AJ40: Nov | AK40: 12 | AL40: 0 | AM40: 1121.87 | AN40: tier - 3 | AO40: tier - 1 | AP40: R1013
...

Sheet Data Transformation
A1: name | B1: 1 | C1: Title | D1: First Name | E1: Last Name | F1: 2 | G1: NumberOfMajorSurgeries | H1: 3 | I1: smoker | J1: Heart Issues | K1: smoker | L1: Heart Issues | M1: 4 | N1: BMI | O1: Weight Status | P1: 5 | Q1: HBA1C | R1: Diabetes Status | S1: 6 | T1: year | U1: month | V1: date | W1: Date Of Birth | X1: 7 | Y1: Age | Z1: 8 | AA1: charges | AB1: State ID | AC1: Hospital tier | AD1: Date of collection of the dataset
A2: Hawks, Ms. Kelly | C2: Ms | D2: Kelly | E2: Hawks | G2: 0 | I2: yes | J2: No | K2: =PROPER(I2) -> Yes | L2: =PROPER(J2) -> No | N2: 47.41 | O2: =IF(N2<18.5,"UNDERWEIGHT",IF(AND(N2>=18.5,N2<=24.9),"NORMAL WEIGHT",IF(AND(N2>=25,N2<=29.9),"OVERWEIGHT",IF(N2>=30,"OBESITY","")))) -> OBESITY | Q2: 7.47 | R2: =IF(Q2<5.7,"NORMAL",IF(AND(Q2>=5.7,Q2<=6.4),"PREDIABETES",IF(Q2>6.4,"DIABETES"))) -> DIABETES | T2: 1992 | U2: Jul | V2: 9 | W2: =CONCATENATE(V2,"-",U2,"-",T2) -> 9-Jul-1992 | Y2: =DATEDIF(W2,$AD$2,"y") -> 30 | AA2: 563.84 | AB2: R1013 | AC2: tier - 2 | AD2: 45085
A3: Lehner, Mr. Matthew D | C3: Mr | D3: Matthew D | E3: Lehner | G3: 0 | I3: yes | J3: No | K3: =PROPER(I3) -> Yes | L3: =PROPER(J3) -> No | N3: 30.36 | O3: =IF(N3<18.5,"UNDERWEIGHT",IF(AND(N3>=18.5,N3<=24.9),"NORMAL WEIGHT",IF(AND(N3>=25,N3<=29.9),"OVERWEIGHT",IF(N3>=30,"OBESITY","")))) -> OBESITY | Q3: 5.77 | R3: =IF(Q3<5.7,"NORMAL",IF(AND(Q3>=5.7,Q3<=6.4),"PREDIABETES",IF(Q3>6.4,"DIABETES"))) -> PREDIABETES | T3: 1992 | U3: Nov | V3: 30 | W3: =CONCATENATE(V3,"-",U3,"-",T3) -> 30-Nov-1992 | Y3: =DATEDIF(W3,$AD$2,"y") -> 30 | AA3: 570.62 | AB3: R1013 | AC3: tier - 2
A4: Lu, Mr. Phil | C4: Mr | D4: Phil | E4: Lu | G4: 2 | I4: yes | J4: yes | K4: =PROPER(I4) -> Yes | L4: =PROPER(J4) -> Yes | N4: 34.485 | O4: =IF(N4<18.5,"UNDERWEIGHT",IF(AND(N4>=18.5,N4<=24.9),"NORMAL WEIGHT",IF(AND(N4>=25,N4<=29.9),"OVERWEIGHT",IF(N4>=30,"OBESITY","")))) -> OBESITY | Q4: 11.87 | R4: =IF(Q4<5.7,"NORMAL",IF(AND(Q4>=5.7,Q4<=6.4),"PREDIABETES",IF(Q4>6.4,"DIABETES"))) -> DIABETES | T4: 1993 | U4: Jun | V4: 30 | W4: =CONCATENATE(V4,"-",U4,"-",T4) -> 30-Jun-1993 | Y4: =DATEDIF(W4,$AD$2,"y") -> 29 | AA4: 600 | AB4: R1013 | AC4: tier - 2
A5: Osborne, Ms. Kelsey | C5: Ms | D5: Kelsey | E5: Osborne | G5: 0 | I5: yes | J5: No | K5: =PROPER(I5) -> Yes | L5: =PROPER(J5) -> No | N5: 38.095 | O5: =IF(N5<18.5,"UNDERWEIGHT",IF(AND(N5>=18.5,N5<=24.9),"NORMAL WEIGHT",IF(AND(N5>=25,N5<=29.9),"OVERWEIGHT",IF(N5>=30,"OBESITY","")))) -> OBESITY | Q5: 6.05 | R5: =IF(Q5<5.7,"NORMAL",IF(AND(Q5>=5.7,Q5<=6.4),"PREDIABETES",IF(Q5>6.4,"DIABETES"))) -> PREDIABETES | T5: 1992 | U5: Sep | V5: 13 | W5: =CONCATENATE(V5,"-",U5,"-",T5) -> 13-Sep-1992 | Y5: =DATEDIF(W5,$AD$2,"y") -> 30 | AA5: 604.54 | AB5: R1013 | AC5: tier - 3
A6: Kadala, Ms. Kristyn | C6: Ms | D6: Kristyn | E6: Kadala | G6: 0 | I6: yes | J6: No | K6: =PROPER(I6) -> Yes | L6: =PROPER(J6) -> No | N6: 35.53 | O6: =IF(N6<18.5,"UNDERWEIGHT",IF(AND(N6>=18.5,N6<=24.9),"NORMAL WEIGHT",IF(AND(N6>=25,N6<=29.9),"OVERWEIGHT",IF(N6>=30,"OBESITY","")))) -> OBESITY | Q6: 5.45 | R6: =IF(Q6<5.7,"NORMAL",IF(AND(Q6>=5.7,Q6<=6.4),"PREDIABETES",IF(Q6>6.4,"DIABETES"))) -> NORMAL | T6: 1998 | U6: Jul | V6: 27 | W6: =CONCATENATE(V6,"-",U6,"-",T6) -> 27-Jul-1998 | Y6: =DATEDIF(W6,$AD$2,"y") -> 24 | AA6: 637.26 | AB6: R1013 | AC6: tier - 3
A7: Baker, Mr. Russell B. | C7: Mr | D7: Russell B | E7: Baker | G7: 0 | I7: yes | J7: No | K7: =PROPER(I7) -> Yes | L7: =PROPER(J7) -> No | N7: 32.8 | O7: =IF(N7<18.5,"UNDERWEIGHT",IF(AND(N7>=18.5,N7<=24.9),"NORMAL WEIGHT",IF(AND(N7>=25,N7<=29.9),"OVERWEIGHT",IF(N7>=30,"OBESITY","")))) -> OBESITY | Q7: 6.59 | R7: =IF(Q7<5.7,"NORMAL",IF(AND(Q7>=5.7,Q7<=6.4),"PREDIABETES",IF(Q7>6.4,"DIABETES"))) -> DIABETES | T7: 2001 | U7: Nov | V7: 20 | W7: =CONCATENATE(V7,"-",U7,"-",T7) -> 20-Nov-2001 | Y7: =DATEDIF(W7,$AD$2,"y") -> 21 | AA7: 646.14 | AB7: R1012 | AC7: tier - 3
A8: Macpherson, Mr. Scott | C8: Mr | D8: Scott | E8: Macpherson | G8: 0 | I8: yes | J8: No | K8: =PROPER(I8) -> Yes | L8: =PROPER(J8) -> No | N8: 36.4 | O8: =IF(N8<18.5,"UNDERWEIGHT",IF(AND(N8>=18.5,N8<=24.9),"NORMAL WEIGHT",IF(AND(N8>=25,N8<=29.9),"OVERWEIGHT",IF(N8>=30,"OBESITY","")))) -> OBESITY | Q8: 6.07 | R8: =IF(Q8<5.7,"NORMAL",IF(AND(Q8>=5.7,Q8<=6.4),"PREDIABETES",IF(Q8>6.4,"DIABETES"))) -> PREDIABETES | T8: 1993 | U8: Jun | V8: 1 | W8: =CONCATENATE(V8,"-",U8,"-",T8) -> 1-Jun-1993 | Y8: =DATEDIF(W8,$AD$2,"y") -> 30 | AA8: 650 | AB8: R1013 | AC8: tier - 3
A9: Hallman, Mr. Stephen | C9: Mr | D9: Stephen | E9: Hallman | G9: 3 | I9: yes | J9: No | K9: =PROPER(I9) -> Yes | L9: =PROPER(J9) -> No | N9: 36.96 | O9: =IF(N9<18.5,"UNDERWEIGHT",IF(AND(N9>=18.5,N9<=24.9),"NORMAL WEIGHT",IF(AND(N9>=25,N9<=29.9),"OVERWEIGHT",IF(N9>=30,"OBESITY","")))) -> OBESITY | Q9: 7.93 | R9: =IF(Q9<5.7,"NORMAL",IF(AND(Q9>=5.7,Q9<=6.4),"PREDIABETES",IF(Q9>6.4,"DIABETES"))) -> DIABETES | T9: 1995 | U9: Jul | V9: 4 | W9: =CONCATENATE(V9,"-",U9,"-",T9) -> 4-Jul-1995 | Y9: =DATEDIF(W9,$AD$2,"y") -> 27 | AA9: 650 | AB9: R1013 | AC9: tier - 3
A10: Moran, Mr. Patrick R. | C10: Mr | D10: Patrick R | E10: Moran | G10: 1 | I10: yes | J10: yes | K10: =PROPER(I10) -> Yes | L10: =PROPER(J10) -> Yes | N10: 41.14 | O10: =IF(N10<18.5,"UNDERWEIGHT",IF(AND(N10>=18.5,N10<=24.9),"NORMAL WEIGHT",IF(AND(N10>=25,N10<=29.9),"OVERWEIGHT",IF(N10>=30,"OBESITY","")))) -> OBESITY | Q10: 9.58 | R10: =IF(Q10<5.7,"NORMAL",IF(AND(Q10>=5.7,Q10<=6.4),"PREDIABETES",IF(Q10>6.4,"DIABETES"))) -> DIABETES | T10: 2002 | U10: Nov | V10: 29 | W10: =CONCATENATE(V10,"-",U10,"-",T10) -> 29-Nov-2002 | Y10: =DATEDIF(W10,$AD$2,"y") -> 20 | AA10: 668 | AB10: R1012 | AC10: tier - 3
A11: Benner, Ms. Brooke N. | C11: Ms | D11: Brooke N | E11: Benner | G11: 0 | I11: yes | J11: No | K11: =PROPER(I11) -> Yes | L11: =PROPER(J11) -> No | N11: 38.06 | O11: =IF(N11<18.5,"UNDERWEIGHT",IF(AND(N11>=18.5,N11<=24.9),"NORMAL WEIGHT",IF(AND(N11>=25,N11<=29.9),"OVERWEIGHT",IF(N11>=30,"OBESITY","")))) -> OBESITY | Q11: 10.79 | R11: =IF(Q11<5.7,"NORMAL",IF(AND(Q11>=5.7,Q11<=6.4),"PREDIABETES",IF(Q11>6.4,"DIABETES"))) -> DIABETES | T11: 1997 | U11: Nov | V11: 9 | W11: =CONCATENATE(V11,"-",U11,"-",T11) -> 9-Nov-1997 | Y11: =DATEDIF(W11,$AD$2,"y") -> 25 | AA11: 670 | AB11: R1013 | AC11: tier - 3
A12: Fierro Vargas, Ms. Paola Andrea | C12: Ms | D12: Paola Andrea | E12: Fierro Vargas | G12: 2 | I12: yes | J12: yes | K12: =PROPER(I12) -> Yes | L12: =PROPER(J12) -> Yes | N12: 37.7 | O12: =IF(N12<18.5,"UNDERWEIGHT",IF(AND(N12>=18.5,N12<=24.9),"NORMAL WEIGHT",IF(AND(N12>=25,N12<=29.9),"OVERWEIGHT",IF(N12>=30,"OBESITY","")))) -> OBESITY | Q12: 5.96 | R12: =IF(Q12<5.7,"NORMAL",IF(AND(Q12>=5.7,Q12<=6.4),"PREDIABETES",IF(Q12>6.4,"DIABETES"))) -> PREDIABETES | T12: 2001 | U12: Sep | V12: 12 | W12: =CONCATENATE(V12,"-",U12,"-",T12) -> 12-Sep-2001 | Y12: =DATEDIF(W12,$AD$2,"y") -> 21 | AA12: 687.54 | AB12: R1013 | AC12: tier - 3
A13: Franz, Mr. David | C13: Mr | D13: David | E13: Franz | G13: 0 | I13: yes | J13: No | K13: =PROPER(I13) -> Yes | L13: =PROPER(J13) -> No | N13: 42.13 | O13: =IF(N13<18.5,"UNDERWEIGHT",IF(AND(N13>=18.5,N13<=24.9),"NORMAL WEIGHT",IF(AND(N13>=25,N13<=29.9),"OVERWEIGHT",IF(N13>=30,"OBESITY","")))) -> OBESITY | Q13: 11.9 | R13: =IF(Q13<5.7,"NORMAL",IF(AND(Q13>=5.7,Q13<=6.4),"PREDIABETES",IF(Q13>6.4,"DIABETES"))) -> DIABETES | T13: 1999 | U13: Dec | V13: 26 | W13: =CONCATENATE(V13,"-",U13,"-",T13) -> 26-Dec-1999 | Y13: =DATEDIF(W13,$AD$2,"y") -> 23 | AA13: 700 | AB13: R1013 | AC13: tier - 2
A14: Foster, Mr. Wade | C14: Mr | D14: Wade | E14: Foster | G14: 0 | I14: yes | J14: No | K14: =PROPER(I14) -> Yes | L14: =PROPER(J14) -> No | N14: 40.92 | O14: =IF(N14<18.5,"UNDERWEIGHT",IF(AND(N14>=18.5,N14<=24.9),"NORMAL WEIGHT",IF(AND(N14>=25,N14<=29.9),"OVERWEIGHT",IF(N14>=30,"OBESITY","")))) -> OBESITY | Q14: 8.41 | R14: =IF(Q14<5.7,"NORMAL",IF(AND(Q14>=5.7,Q14<=6.4),"PREDIABETES",IF(Q14>6.4,"DIABETES"))) -> DIABETES | T14: 1999 | U14: Dec | V14: 14 | W14: =CONCATENATE(V14,"-",U14,"-",T14) -> 14-Dec-1999 | Y14: =DATEDIF(W14,$AD$2,"y") -> 23 | AA14: 722.99 | AB14: R1013 | AC14: tier - 3
... A2336: German, Mr. Aaron K | C2336: Mr | D2336: Aaron K | E2336: German | G2336: 1 | I2336: No | J2336: No | K2336: =PROPER(I2336) -> No | L2336: =PROPER(J2336) -> No | N2336: 17.58 | O2336: =IF(N2336<18.5,"UNDERWEIGHT",IF(AND(N2336>=18.5,N2336<=24.9),"NORMAL WEIGHT",IF(AND(N2336>=25,N2336<=29.9),"OVERWEIGHT",IF(N2336>=30,"OBESITY","")))) -> UNDERWEIGHT | Q2336: 4.51 | R2336: =IF(Q2336<5.7,"NORMAL",IF(AND(Q2336>=5.7,Q2336<=6.4),"PREDIABETES",IF(Q2336>6.4,"DIABETES"))) -> NORMAL | T2336: 1963 | U2336: Sep | V2336: 4 | W2336: =CONCATENATE(V2336,"-",U2336,"-",T2336) -> 4-Sep-1963 | Y2336: =DATEDIF(W2336,$AD$2,"y") -> 59 | AA2336: 48970.25 | AB2336: R1013 | AC2336: tier - 1
T2337: 1958 | U2337: Jun | V2337: 27 | W2337: =CONCATENATE(V2337,"-",U2337,"-",T2337) -> 27-Jun-1958 | Y2337: =DATEDIF(W2337,$AD$2,"y") -> 64 | AA2337: 49577.66 | AB2337: R1013 | AC2337: tier - 2
T2338: 1994 | U2338: Oct | V2338: 27 | W2338: =CONCATENATE(V2338,"-",U2338,"-",T2338) -> 27-Oct-1994 | Y2338: =DATEDIF(W2338,$AD$2,"y") -> 28 | AA2338: 51194.56 | AB2338: R1011 | AC2338: tier - 1
T2339: 1962 | U2339: Aug | V2339: 4 | W2339: =CONCATENATE(V2339,"-",U2339,"-",T2339) -> 4-Aug-1962 | Y2339: =DATEDIF(W2339,$AD$2,"y") -> 60 | AA2339: 52590.83 | AB2339: R1011 | AC2339: tier - 1
T2340: 1989 | U2340: Jun | V2340: 19 | W2340: =CONCATENATE(V2340,"-",U2340,"-",T2340) -> 19-Jun-1989 | Y2340: =DATEDIF(W2340,$AD$2,"y") -> 33 | AA2340: 55135.4 | AB2340: R1012 | AC2340: tier - 1
T2341: 1991 | U2341: Jun | V2341: 6 | W2341: =CONCATENATE(V2341,"-",U2341,"-",T2341) -> 6-Jun-1991 | Y2341: =DATEDIF(W2341,$AD$2,"y") -> 32 | AA2341: 58571.07 | AB2341: R1024 | AC2341: tier - 1
T2342: 1970 | U2342: Sep | V2342: 11 | W2342: =CONCATENATE(V2342,"-",U2342,"-",T2342) -> 11-Sep-1970 | Y2342: =DATEDIF(W2342,$AD$2,"y") -> 52 | AA2342: 60021.4 | AB2342: R1012 | AC2342: tier - 1
T2343: 1977 | U2343: Jun | V2343: 8 | W2343: =CONCATENATE(V2343,"-",U2343,"-",T2343) -> 8-Jun-1977 | Y2343: =DATEDIF(W2343,$AD$2,"y") -> 46 | AA2343: 62592.87 | AB2343: R1013 | AC2343: tier - 2
T2344: 1968 | U2344: Oct | V2344: 12 | W2344: =CONCATENATE(V2344,"-",U2344,"-",T2344) -> 12-Oct-1968 | Y2344: =DATEDIF(W2344,$AD$2,"y") -> 54 | AA2344: 63770.43 | AB2344: R1013 | AC2344: tier - 1

Sheet HEALTHCARE
A1: 1
A2: Customer ID | B2: NAME | C2: BMI | D2: HBA1C | E2: HEART ISSUES | F2: ANY TRANSPLANTS | G2: CANCER HISTORY | H2: NO:OF MAJOR SURGERIES | I2: SMOKER | J2: WEIGHT STATUS | K2: DIABETES STATUS | L2: DATE OF BIRTH | M2: CHARGES | N2: HOSPITAL TIER | O2: CITY TIER | P2: STATE ID | Q2: AGE
A3: Id1 | B3: =VLOOKUP(A3,'Customer Names'!A1:C2336,3,FALSE) -> Kelly | C3: =VLOOKUP(A3,'Medical Examinations'!A1:H2336,2,FALSE) -> 47.41 | D3: =VLOOKUP(A3,'Medical Examinations'!A1:H2336,3,FALSE) -> 7.47 | E3: =VLOOKUP(A3,'Medical Examinations'!A1:H2336,4,FALSE) -> No | F3: =VLOOKUP(A3,'Medical Examinations'!A1:H2336,5,FALSE) -> No | G3: =VLOOKUP(A3,'Medical Examinations'!A1:H2336,6,FALSE) -> No | H3: =VLOOKUP(A3,'Medical Examinations'!A1:H2336,7,FALSE) -> 0 | I3: =VLOOKUP(A3,'Medical Examinations'!A1:H2336,8,FALSE) -> yes | J3: =VLOOKUP(A3,'Medical Examinations'!A1:J2336,9,FALSE) -> OBESITY | K3: =VLOOKUP(A3,'Medical Examinations'!A1:J2336,10,FALSE) -> DIABETES | L3: =VLOOKUP(A3,'Hospitalisation Details'!A1:J2344,10,FALSE) -> 12-Oct-1968 | M3: =VLOOKUP(A3,'Hospitalisation Details'!A1:I2344,6,FALSE) -> 63770.43 | N3: =VLOOKUP(A3,'Hospitalisation Details'!A1:I2344,7,FALSE) -> tier - 1 | O3: =VLOOKUP(A3,'Hospitalisation Details'!A1:I2344,8,FALSE) -> tier - 3 | P3: =VLOOKUP(A3,'Hospitalisation Details'!A1:I2344,9,FALSE) -> R1013 | Q3: =VLOOKUP(A3,'Hospitalisation Details'!A1:K2344,11,FALSE) -> 57
A4: Id2 | B4: =VLOOKUP(A4,'Customer Names'!A2:C2337,3,FALSE) -> Matthew D | C4: =VLOOKUP(A4,'Medical Examinations'!A2:H2337,2,FALSE) -> 30.36 | D4: =VLOOKUP(A4,'Medical Examinations'!A2:H2337,3,FALSE) -> 5.77 | E4: =VLOOKUP(A4,'Medical Examinations'!A2:H2337,4,FALSE) -> No | F4: =VLOOKUP(A4,'Medical Examinations'!A2:H2337,5,FALSE) -> No | G4: =VLOOKUP(A4,'Medical Examinations'!A2:H2337,6,FALSE) -> No | H4: =VLOOKUP(A4,'Medical Examinations'!A2:H2337,7,FALSE) -> 0 | I4: =VLOOKUP(A4,'Medical Examinations'!A2:H2337,8,FALSE) -> yes | J4: =VLOOKUP(A4,'Medical Examinations'!A2:J2337,9,FALSE) -> OBESITY | K4: =VLOOKUP(A4,'Medical Examinations'!A2:J2337,10,FALSE) -> PREDIABETES | L4: =VLOOKUP(A4,'Hospitalisation Details'!A2:J2345,10,FALSE) -> 8-Jun-1977 | M4: =VLOOKUP(A4,'Hospitalisation Details'!A2:I2345,6,FALSE) -> 62592.87 | N4: =VLOOKUP(A4,'Hospitalisation Details'!A2:I2345,7,FALSE) -> tier - 2 | O4: =VLOOKUP(A4,'Hospitalisation Details'!A2:I2345,8,FALSE) -> tier - 3 | P4: =VLOOKUP(A4,'Hospitalisation Details'!A2:I2345,9,FALSE) -> R1013 | Q4: =VLOOKUP(A4,'Hospitalisation Details'!A2:K2345,11,FALSE) -> 48
A5: Id3 | B5: =VLOOKUP(A5,'Customer Names'!A3:C2338,3,FALSE) -> Phil | C5: =VLOOKUP(A5,'Medical Examinations'!A3:H2338,2,FALSE) -> 34.485 | D5: =VLOOKUP(A5,'Medical Examinations'!A3:H2338,3,FALSE) -> 11.87 | E5: =VLOOKUP(A5,'Medical Examinations'!A3:H2338,4,FALSE) -> yes | F5: =VLOOKUP(A5,'Medical Examinations'!A3:H2338,5,FALSE) -> No | G5: =VLOOKUP(A5,'Medical Examinations'!A3:H2338,6,FALSE) -> No | H5: =VLOOKUP(A5,'Medical Examinations'!A3:H2338,7,FALSE) -> 2 | I5: =VLOOKUP(A5,'Medical Examinations'!A3:H2338,8,FALSE) -> yes | J5: =VLOOKUP(A5,'Medical Examinations'!A3:J2338,9,FALSE) -> OBESITY | K5: =VLOOKUP(A5,'Medical Examinations'!A3:J2338,10,FALSE) -> DIABETES | L5: =VLOOKUP(A5,'Hospitalisation Details'!A3:J2346,10,FALSE) -> 11-Sep-1970 | M5: =VLOOKUP(A5,'Hospitalisation Details'!A3:I2346,6,FALSE) -> 60021.4 | N5: =VLOOKUP(A5,'Hospitalisation Details'!A3:I2346,7,FALSE) -> tier - 1 | O5: =VLOOKUP(A5,'Hospitalisation Details'!A3:I2346,8,FALSE) -> tier - 1 | P5: =VLOOKUP(A5,'Hospitalisation Details'!A3:I2346,9,FALSE) -> R1012 | Q5: =VLOOKUP(A5,'Hospitalisation Details'!A3:K2346,11,FALSE) -> 55
A6: Id4 | B6: =VLOOKUP(A6,'Customer Names'!A4:C2339,3,FALSE) -> Kelsey | C6: =VLOOKUP(A6,'Medical Examinations'!A4:H2339,2,FALSE) -> 38.095 | D6: =VLOOKUP(A6,'Medical Examinations'!A4:H2339,3,FALSE) -> 6.05 | E6: =VLOOKUP(A6,'Medical Examinations'!A4:H2339,4,FALSE) -> No | F6: =VLOOKUP(A6,'Medical Examinations'!A4:H2339,5,FALSE) -> No | G6: =VLOOKUP(A6,'Medical Examinations'!A4:H2339,6,FALSE) -> No | H6: =VLOOKUP(A6,'Medical Examinations'!A4:H2339,7,FALSE) -> 0 | I6: =VLOOKUP(A6,'Medical Examinations'!A4:H2339,8,FALSE) -> yes | J6: =VLOOKUP(A6,'Medical Examinations'!A4:J2339,9,FALSE) -> OBESITY | K6: =VLOOKUP(A6,'Medical Examinations'!A4:J2339,10,FALSE) -> PREDIABETES | L6: =VLOOKUP(A6,'Hospitalisation Details'!A4:J2347,10,FALSE) -> 6-Jun-1991 | M6: =VLOOKUP(A6,'Hospitalisation Details'!A4:I2347,6,FALSE) -> 58571.07 | N6: =VLOOKUP(A6,'Hospitalisation Details'!A4:I2347,7,FALSE) -> tier - 1 | O6: =VLOOKUP(A6,'Hospitalisation Details'!A4:I2347,8,FALSE) -> tier - 3 | P6: =VLOOKUP(A6,'Hospitalisation Details'!A4:I2347,9,FALSE) -> R1024 | Q6: =VLOOKUP(A6,'Hospitalisation Details'!A4:K2347,11,FALSE) -> 34
A7: Id5 | B7: =VLOOKUP(A7,'Customer Names'!A5:C2340,3,FALSE) -> Kristyn | C7: =VLOOKUP(A7,'Medical Examinations'!A5:H2340,2,FALSE) -> 35.53 | D7: =VLOOKUP(A7,'Medical Examinations'!A5:H2340,3,FALSE) -> 5.45 | E7: =VLOOKUP(A7,'Medical Examinations'!A5:H2340,4,FALSE) -> No | F7: =VLOOKUP(A7,'Medical Examinations'!A5:H2340,5,FALSE) -> No | G7: =VLOOKUP(A7,'Medical Examinations'!A5:H2340,6,FALSE) -> No | H7: =VLOOKUP(A7,'Medical Examinations'!A5:H2340,7,FALSE) -> 0 | I7: =VLOOKUP(A7,'Medical Examinations'!A5:H2340,8,FALSE) -> yes | J7: =VLOOKUP(A7,'Medical Examinations'!A5:J2340,9,FALSE) -> OBESITY | K7: =VLOOKUP(A7,'Medical Examinations'!A5:J2340,10,FALSE) -> NORMAL | L7: =VLOOKUP(A7,'Hospitalisation Details'!A5:J2348,10,FALSE) -> 19-Jun-1989 | M7: =VLOOKUP(A7,'Hospitalisation Details'!A5:I2348,6,FALSE) -> 55135.4 | N7: =VLOOKUP(A7,'Hospitalisation Details'!A5:I2348,7,FALSE) -> tier - 1 | O7: =VLOOKUP(A7,'Hospitalisation Details'!A5:I2348,8,FALSE) -> tier - 2 | P7: =VLOOKUP(A7,'Hospitalisation Details'!A5:I2348,9,FALSE) -> R1012 | Q7: =VLOOKUP(A7,'Hospitalisation Details'!A5:K2348,11,FALSE) -> 36
A8: Id6 | B8: =VLOOKUP(A8,'Customer Names'!A6:C2341,3,FALSE) -> Russell B. | C8: =VLOOKUP(A8,'Medical Examinations'!A6:H2341,2,FALSE) -> 32.8 | D8: =VLOOKUP(A8,'Medical Examinations'!A6:H2341,3,FALSE) -> 6.59 | E8: =VLOOKUP(A8,'Medical Examinations'!A6:H2341,4,FALSE) -> No | F8: =VLOOKUP(A8,'Medical Examinations'!A6:H2341,5,FALSE) -> No | G8: =VLOOKUP(A8,'Medical Examinations'!A6:H2341,6,FALSE) -> No | H8: =VLOOKUP(A8,'Medical Examinations'!A6:H2341,7,FALSE) -> 0 | I8: =VLOOKUP(A8,'Medical Examinations'!A6:H2341,8,FALSE) -> yes | J8: =VLOOKUP(A8,'Medical Examinations'!A6:J2341,9,FALSE) -> OBESITY | K8: =VLOOKUP(A8,'Medical Examinations'!A6:J2341,10,FALSE) -> DIABETES | L8: =VLOOKUP(A8,'Hospitalisation Details'!A6:J2349,10,FALSE) -> 4-Aug-1962 | M8: =VLOOKUP(A8,'Hospitalisation Details'!A6:I2349,6,FALSE) -> 52590.83 | N8: =VLOOKUP(A8,'Hospitalisation Details'!A6:I2349,7,FALSE) -> tier - 1 | O8: =VLOOKUP(A8,'Hospitalisation Details'!A6:I2349,8,FALSE) -> tier - 3 | P8: =VLOOKUP(A8,'Hospitalisation Details'!A6:I2349,9,FALSE) -> R1011 | Q8: =VLOOKUP(A8,'Hospitalisation Details'!A6:K2349,11,FALSE) -> 63
A9: Id7 | B9: =VLOOKUP(A9,'Customer Names'!A7:C2342,3,FALSE) -> Scott | C9: =VLOOKUP(A9,'Medical Examinations'!A7:H2342,2,FALSE) -> 36.4 | D9: =VLOOKUP(A9,'Medical Examinations'!A7:H2342,3,FALSE) -> 6.07 | E9: =VLOOKUP(A9,'Medical Examinations'!A7:H2342,4,FALSE) -> No | F9: =VLOOKUP(A9,'Medical Examinations'!A7:H2342,5,FALSE) -> No | G9: =VLOOKUP(A9,'Medical Examinations'!A7:H2342,6,FALSE) -> No | H9: =VLOOKUP(A9,'Medical Examinations'!A7:H2342,7,FALSE) -> 0 | I9: =VLOOKUP(A9,'Medical Examinations'!A7:H2342,8,FALSE) -> yes | J9: =VLOOKUP(A9,'Medical Examinations'!A7:J2342,9,FALSE) -> OBESITY | K9: =VLOOKUP(A9,'Medical Examinations'!A7:J2342,10,FALSE) -> PREDIABETES | L9: =VLOOKUP(A9,'Hospitalisation Details'!A7:J2350,10,FALSE) -> 27-Oct-1994 | M9: =VLOOKUP(A9,'Hospitalisation Details'!A7:I2350,6,FALSE) -> 51194.56 | N9: =VLOOKUP(A9,'Hospitalisation Details'!A7:I2350,7,FALSE) -> tier - 1 | O9: =VLOOKUP(A9,'Hospitalisation Details'!A7:I2350,8,FALSE) -> tier - 3 | P9: =VLOOKUP(A9,'Hospitalisation Details'!A7:I2350,9,FALSE) -> R1011 | Q9: =VLOOKUP(A9,'Hospitalisation Details'!A7:K2350,11,FALSE) -> 31
A10: Id8 | B10: =VLOOKUP(A10,'Customer Names'!A8:C2343,3,FALSE) -> Stephen | C10: =VLOOKUP(A10,'Medical Examinations'!A8:H2343,2,FALSE) -> 36.96 | D10: =VLOOKUP(A10,'Medical Examinations'!A8:H2343,3,FALSE) -> 7.93 | E10: =VLOOKUP(A10,'Medical Examinations'!A8:H2343,4,FALSE) -> No | F10: =VLOOKUP(A10,'Medical Examinations'!A8:H2343,5,FALSE) -> No | G10: =VLOOKUP(A10,'Medical Examinations'!A8:H2343,6,FALSE) -> No | H10: =VLOOKUP(A10,'Medical Examinations'!A8:H2343,7,FALSE) -> 3 | I10: =VLOOKUP(A10,'Medical Examinations'!A8:H2343,8,FALSE) -> yes | J10: =VLOOKUP(A10,'Medical Examinations'!A8:J2343,9,FALSE) -> OBESITY | K10: =VLOOKUP(A10,'Medical Examinations'!A8:J2343,10,FALSE) -> DIABETES | L10: =VLOOKUP(A10,'Hospitalisation Details'!A8:J2351,10,FALSE) -> 27-Jun-1958 | M10: =VLOOKUP(A10,'Hospitalisation Details'!A8:I2351,6,FALSE) -> 49577.66 | N10: =VLOOKUP(A10,'Hospitalisation Details'!A8:I2351,7,FALSE) -> tier - 2 | O10: =VLOOKUP(A10,'Hospitalisation Details'!A8:I2351,8,FALSE) -> tier - 2 | P10: =VLOOKUP(A10,'Hospitalisation Details'!A8:I2351,9,FALSE) -> R1013 | Q10: =VLOOKUP(A10,'Hospitalisation Details'!A8:K2351,11,FALSE) -> 67
A11: Id9 | B11: =VLOOKUP(A11,'Customer Names'!A9:C2344,3,FALSE) -> Patrick R. | C11: =VLOOKUP(A11,'Medical Examinations'!A9:H2344,2,FALSE) -> 41.14 | D11: =VLOOKUP(A11,'Medical Examinations'!A9:H2344,3,FALSE) -> 9.58 | E11: =VLOOKUP(A11,'Medical Examinations'!A9:H2344,4,FALSE) -> yes | F11: =VLOOKUP(A11,'Medical Examinations'!A9:H2344,5,FALSE) -> No | G11: =VLOOKUP(A11,'Medical Examinations'!A9:H2344,6,FALSE) -> Yes | H11: =VLOOKUP(A11,'Medical Examinations'!A9:H2344,7,FALSE) -> 1 | I11: =VLOOKUP(A11,'Medical Examinations'!A9:H2344,8,FALSE) -> yes | J11: =VLOOKUP(A11,'Medical Examinations'!A9:J2344,9,FALSE) -> OBESITY | K11: =VLOOKUP(A11,'Medical Examinations'!A9:J2344,10,FALSE) -> DIABETES | L11: =VLOOKUP(A11,'Hospitalisation Details'!A9:J2352,10,FALSE) -> 4-Sep-1963 | M11: =VLOOKUP(A11,'Hospitalisation Details'!A9:I2352,6,FALSE) -> 48970.25 | N11: =VLOOKUP(A11,'Hospitalisation Details'!A9:I2352,7,FALSE) -> tier - 1 | O11: =VLOOKUP(A11,'Hospitalisation Details'!A9:I2352,8,FALSE) -> tier - 2 | P11: =VLOOKUP(A11,'Hospitalisation Details'!A9:I2352,9,FALSE) -> R1013 | Q11: =VLOOKUP(A11,'Hospitalisation Details'!A9:K2352,11,FALSE) -> 62
A12: Id10 | B12: =VLOOKUP(A12,'Customer Names'!A10:C2345,3,FALSE) -> Brooke N. | C12: =VLOOKUP(A12,'Medical Examinations'!A10:H2345,2,FALSE) -> 38.06 | D12: =VLOOKUP(A12,'Medical Examinations'!A10:H2345,3,FALSE) -> 10.79 | E12: =VLOOKUP(A12,'Medical Examinations'!A10:H2345,4,FALSE) -> No | F12: =VLOOKUP(A12,'Medical Examinations'!A10:H2345,5,FALSE) -> No | G12: =VLOOKUP(A12,'Medical Examinations'!A10:H2345,6,FALSE) -> No | H12: =VLOOKUP(A12,'Medical Examinations'!A10:H2345,7,FALSE) -> 0 | I12: =VLOOKUP(A12,'Medical Examinations'!A10:H2345,8,FALSE) -> yes | J12: =VLOOKUP(A12,'Medical Examinations'!A10:J2345,9,FALSE) -> OBESITY | K12: =VLOOKUP(A12,'Medical Examinations'!A10:J2345,10,FALSE) -> DIABETES | L12: =VLOOKUP(A12,'Hospitalisation Details'!A10:J2353,10,FALSE) -> 29-Dec-1978 | M12: =VLOOKUP(A12,'Hospitalisation Details'!A10:I2353,6,FALSE) -> 48885.14 | N12: =VLOOKUP(A12,'Hospitalisation Details'!A10:I2353,7,FALSE) -> tier - 1 | O12: =VLOOKUP(A12,'Hospitalisation Details'!A10:I2353,8,FALSE) -> tier - 2 | P12: =VLOOKUP(A12,'Hospitalisation Details'!A10:I2353,9,FALSE) -> R1013 | Q12: =VLOOKUP(A12,'Hospitalisation Details'!A10:K2353,11,FALSE) -> 46
A13: Id11 | B13: =VLOOKUP(A13,'Customer Names'!A11:C2346,3,FALSE) -> Ms. Paola Andrea | C13: =VLOOKUP(A13,'Medical Examinations'!A11:H2346,2,FALSE) -> 37.7 | D13: =VLOOKUP(A13,'Medical Examinations'!A11:H2346,3,FALSE) -> 5.96 | E13: =VLOOKUP(A13,'Medical Examinations'!A11:H2346,4,FALSE) -> yes | F13: =VLOOKUP(A13,'Medical Examinations'!A11:H2346,5,FALSE) -> No | G13: =VLOOKUP(A13,'Medical Examinations'!A11:H2346,6,FALSE) -> No | H13: =VLOOKUP(A13,'Medical Examinations'!A11:H2346,7,FALSE) -> 2 | I13: =VLOOKUP(A13,'Medical Examinations'!A11:H2346,8,FALSE) -> yes | J13: =VLOOKUP(A13,'Medical Examinations'!A11:J2346,9,FALSE) -> OBESITY | K13: =VLOOKUP(A13,'Medical Examinations'!A11:J2346,10,FALSE) -> PREDIABETES | L13: =VLOOKUP(A13,'Hospitalisation Details'!A11:J2354,10,FALSE) -> 22-Jul-1959 | M13: =VLOOKUP(A13,'Hospitalisation Details'!A11:I2354,6,FALSE) -> 48824.45 | N13: =VLOOKUP(A13,'Hospitalisation Details'!A11:I2354,7,FALSE) -> tier - 2 | O13: =VLOOKUP(A13,'Hospitalisation Details'!A11:I2354,8,FALSE) -> tier - 1 | P13: =VLOOKUP(A13,'Hospitalisation Details'!A11:I2354,9,FALSE) -> R1011 | Q13: =VLOOKUP(A13,'Hospitalisation Details'!A11:K2354,11,FALSE) -> 66
A14: Id12 | B14: =VLOOKUP(A14,'Customer Names'!A12:C2347,3,FALSE) -> David | C14: =VLOOKUP(A14,'Medical Examinations'!A12:H2347,2,FALSE) -> 42.13 | D14: =VLOOKUP(A14,'Medical Examinations'!A12:H2347,3,FALSE) -> 11.9 | E14: =VLOOKUP(A14,'Medical Examinations'!A12:H2347,4,FALSE) -> No | F14: =VLOOKUP(A14,'Medical Examinations'!A12:H2347,5,FALSE) -> No | G14: =VLOOKUP(A14,'Medical Examinations'!A12:H2347,6,FALSE) -> No | H14: =VLOOKUP(A14,'Medical Examinations'!A12:H2347,7,FALSE) -> 0 | I14: =VLOOKUP(A14,'Medical Examinations'!A12:H2347,8,FALSE) -> yes | J14: =VLOOKUP(A14,'Medical Examinations'!A12:J2347,9,FALSE) -> OBESITY | K14: =VLOOKUP(A14,'Medical Examinations'!A12:J2347,10,FALSE) -> DIABETES | L14: =VLOOKUP(A14,'Hospitalisation Details'!A12:J2355,10,FALSE) -> 27-Oct-1965 | M14: =VLOOKUP(A14,'Hospitalisation Details'!A12:I2355,6,FALSE) -> 48675.52 | N14: =VLOOKUP(A14,'Hospitalisation Details'!A12:I2355,7,FALSE) -> tier - 1 | O14: =VLOOKUP(A14,'Hospitalisation Details'!A12:I2355,8,FALSE) -> tier - 2 | P14: =VLOOKUP(A14,'Hospitalisation Details'!A12:I2355,9,FALSE) -> R1013 | Q14: =VLOOKUP(A14,'Hospitalisation Details'!A12:K2355,11,FALSE) -> 60
... A2337: Id2335 | B2337: =VLOOKUP(A2337,'Customer Names'!A2335:C4670,3,FALSE) -> Aaron K | C2337: =VLOOKUP(A2337,'Medical Examinations'!A2335:H4670,2,FALSE) -> 17.58 | D2337: =VLOOKUP(A2337,'Medical Examinations'!A2335:H4670,3,FALSE) -> 4.51 | E2337: =VLOOKUP(A2337,'Medical Examinations'!A2335:H4670,4,FALSE) -> No | F2337: =VLOOKUP(A2337,'Medical Examinations'!A2335:H4670,5,FALSE) -> No | G2337: =VLOOKUP(A2337,'Medical Examinations'!A2335:H4670,6,FALSE) -> No | H2337: =VLOOKUP(A2337,'Medical Examinations'!A2335:H4670,7,FALSE) -> 1 | I2337: =VLOOKUP(A2337,'Medical Examinations'!A2335:H4670,8,FALSE) -> No | J2337: =VLOOKUP(A2337,'Medical Examinations'!A2335:J4670,9,FALSE) -> UNDERWEIGHT | K2337: =VLOOKUP(A2337,'Medical Examinations'!A2335:J4670,10,FALSE) -> NORMAL | L2337: =VLOOKUP(A2337,'Hospitalisation Details'!A2335:J4678,10,FALSE) -> #N/A | M2337: =VLOOKUP(A2337,'Hospitalisation Details'!A2335:I4678,6,FALSE) -> #N/A | N2337: =VLOOKUP(A2337,'Hospitalisation Details'!A2335:I4678,7,FALSE) -> #N/A | O2337: =VLOOKUP(A2337,'Hospitalisation Details'!A2335:I4678,8,FALSE) -> #N/A | P2337: =VLOOKUP(A2337,'Hospitalisation Details'!A2335:I4678,9,FALSE) -> #N/A | Q2337: =VLOOKUP(A2337,'Hospitalisation Details'!A2335:K4678,11,FALSE) -> #N/A

Sheet Data Exploration, Analysis & Vi
A1: 2
A2: SMOKER | B2: No
A4: Cancer History | B4: Count of Customer ID
A5: No | B5: 1540
A6: Yes | B6: 307
A7: Grand Total | B7: 1847
A9: SMOKER | B9: yes
A11: Cancer History | B11: Count of Customer ID
A12: No | B12: 404
A13: Yes | B13: 84
A14: Grand Total | B14: 488
A17: Any Transplants | B17: Sum of NO:OF MAJOR SURGERIES
A18: No | B18: 1417
A19: yes | B19: 162
A20: Grand Total | B20: 1579
A22: Any Transplants | B22: Average of HBA1C
A23: No | B23: 6.6704427
A24: yes | B24: 5.1876389
A25: Grand Total | B25: 6.5789979
A28: 3
A30: Average of charges | B30: DIABETES STATUS
A31: WEIGHT STATUS | B31: DIABETES | C31: NORMAL | D31: PREDIABETES | E31: Grand Total
A32: NORMAL WEIGHT | B32: 11480.921 | C32: 20642.879 | D32: 18711.17 | E32: 17346.316
A33: OBESITY | B33: 7286.7581 | C33: 12339.852 | D33: 11934.612 | E33: 10483.967
A34: OVERWEIGHT | B34: 9686.5719 | C34: 15290.721 | D34: 15837.97 | E34: 13635.461
A35: UNDERWEIGHT | B35: 17850.131 | C35: 26863.078 | D35: 26254.821 | E35: 23386.455
A36: Grand Total | B36: 9375.0175 | C36: 15684.244 | D36: 14989.399 | E36: 13405.573
A39: Average of charges | B39: hospital tier
A40: state ids | B40: tier - 1 | C40: tier - 2 | D40: tier - 3 | E40: Grand Total
A41: R1011 | B41: 33181.289 | C41: 18997.281 | D41: 9250.3618 | E41: 19557.642
A42: R1012 | B42: 25800.402 | C42: 10312.047 | D42: 10179.942 | E42: 11990.384
A43: R1013 | B43: 31371.853 | C43: 8439.2844 | D43: 6857.1092 | E43: 10538.409
A44: R1014 | B44: 13891.86 | C44: 2395.17 | D44: 16950.485 | E44: 13478.057
A45: R1015 | B45: 21523.52 | C45: 16433.907 | D45: 7570.755 | E45: 14489.801
A46: R1016 | B46: 39868.616 | C46: 16075.963 | D46: 8133.0084 | E46: 13589.263
A47: R1017 | B47: 34070.596 | C47: 11365.622 | D47: 8667.3662 | E47: 14806.108
A48: R1018 | B48: 33475.82 | C48: 10139.553 | D48: 12570.97 | E48: 13272.787
A49: R1019 | B49: 27621.61 | C49: 8116.72 | D49: 12706.976 | E49: 13633.143
A50: R1020 | C50: 6760.5433 | D50: 11716.453 | E50: 9238.4983
A51: R1021 | C51: 7668.1787 | D51: 11518.786 | E51: 8933.3781
...

Sheet DASHBOARD
I1: HEALTHCARE DATA ANALYSIS AND INSIGHTS
